Workbook

Sheet HOME

Sheet Dealer Wise
B1: Up to 29.07.2020 | M1: DAYS RUNNING | N1: 19 | O1: WORKING DAY | P1: 20
A2: JULY'20 Back Margin Dealer Wise Value Achievement Status | P2: Rest WD | Q2: =P1-N1 -> 1
A3: SL | B3: Distributors | C3: Region/ Cluster | D3: Zone | E3: Target JULY 2020 | F3: Achievement JULY 2020 | G3: Achievement % JULY 2020 | H3: Remaining for 80% | I3: Daily Required Rate for 80% | J3: Remaining for 86% | K3: Daily Required Rate for 86% | L3: Remaining for 91% | M3: Daily Required Rate for 91% | N3: Remaining for 96% | O3: Daily Required Rate for 96% | P3: Remaining for 100% | Q3: Daily Required Rate for 100%
A4: 1 | B4: A One Tel | C4: Khulna | D4: Barishal | E4: 17333597 | F4: 17424054 | G4: =IFERROR(F4/E4,0) -> 1.0052186 | H4: =(E4*0.8)-F4 -> -3557176.9 | I4: =H4/$Q$2 -> -3557176.9 | J4: =(E4*0.86)-F4 -> -2517161 | K4: =J4/$Q$2 -> -2517161 | L4: =(E4*0.91)-F4 -> -1650481.2 | M4: =L4/$Q$2 -> -1650481.2 | N4: =(E4*0.96)-F4 -> -783801.38 | O4: =N4/$Q$2 -> -783801.38 | P4: =E4-F4 -> -90457.509 | Q4: =P4/$Q$2 -> -90457.509
A5: 2 | B5: Click Mobile Corner | C5: Khulna | D5: Barishal | E5: 6859944.5 | F5: 7148042.4 | G5: =IFERROR(F5/E5,0) -> 1.0419971 | H5: =(E5*0.8)-F5 -> -1660086.8 | I5: =H5/$Q$2 -> -1660086.8 | J5: =(E5*0.86)-F5 -> -1248490.1 | K5: =J5/$Q$2 -> -1248490.1 | L5: =(E5*0.91)-F5 -> -905492.92 | M5: =L5/$Q$2 -> -905492.92 | N5: =(E5*0.96)-F5 -> -562495.7 | O5: =N5/$Q$2 -> -562495.7 | P5: =E5-F5 -> -288097.92 | Q5: =P5/$Q$2 -> -288097.92
A6: 3 | B6: Desh Link | C6: Khulna | D6: Faridpur | E6: 13699000 | F6: 13459413 | G6: =IFERROR(F6/E6,0) -> 0.98251058 | H6: =(E6*0.8)-F6 -> -2500212.5 | I6: =H6/$Q$2 -> -2500212.5 | J6: =(E6*0.86)-F6 -> -1678272.5 | K6: =J6/$Q$2 -> -1678272.5 | L6: =(E6*0.91)-F6 -> -993322.45 | M6: =L6/$Q$2 -> -993322.45 | N6: =(E6*0.96)-F6 -> -308372.44 | O6: =N6/$Q$2 -> -308372.44 | P6: =E6-F6 -> 239587.56 | Q6: =P6/$Q$2 -> 239587.56
A7: 4 | B7: M/S Faiz Enterprise | C7: Khulna | D7: Madaripur | E7: 5170588.2 | F7: 5173323.5 | G7: =IFERROR(F7/E7,0) -> 1.000529 | H7: =(E7*0.8)-F7 -> -1036853 | I7: =H7/$Q$2 -> -1036853 | J7: =(E7*0.86)-F7 -> -726617.69 | K7: =J7/$Q$2 -> -726617.69 | L7: =(E7*0.91)-F7 -> -468088.28 | M7: =L7/$Q$2 -> -468088.28 | N7: =(E7*0.96)-F7 -> -209558.87 | O7: =N7/$Q$2 -> -209558.87 | P7: =E7-F7 -> -2735.3392 | Q7: =P7/$Q$2 -> -2735.3392
A8: 5 | B8: M/S Saad Telecom | C8: Khulna | D8: Madaripur | E8: 7035288.3 | F8: 6443733.5 | G8: =IFERROR(F8/E8,0) -> 0.91591606 | H8: =(E8*0.8)-F8 -> -815502.91 | I8: =H8/$Q$2 -> -815502.91 | J8: =(E8*0.86)-F8 -> -393385.62 | K8: =J8/$Q$2 -> -393385.62 | L8: =(E8*0.91)-F8 -> -41621.206 | M8: =L8/$Q$2 -> -41621.206 | N8: =(E8*0.96)-F8 -> 310143.21 | O8: =N8/$Q$2 -> 310143.21 | P8: =E8-F8 -> 591554.74 | Q8: =P8/$Q$2 -> 591554.74
A9: 6 | B9: M/S. Karachi Store | C9: Khulna | D9: Barishal | E9: 4041446.2 | F9: 4508129.9 | G9: =IFERROR(F9/E9,0) -> 1.1154744 | H9: =(E9*0.8)-F9 -> -1274973 | I9: =H9/$Q$2 -> -1274973 | J9: =(E9*0.86)-F9 -> -1032486.2 | K9: =J9/$Q$2 -> -1032486.2 | L9: =(E9*0.91)-F9 -> -830413.88 | M9: =L9/$Q$2 -> -830413.88 | N9: =(E9*0.96)-F9 -> -628341.57 | O9: =N9/$Q$2 -> -628341.57 | P9: =E9-F9 -> -466683.72 | Q9: =P9/$Q$2 -> -466683.72
A10: 7 | B10: M/S. National Electronics | C10: Khulna | D10: Faridpur | E10: 11560297 | F10: 11021130 | G10: =IFERROR(F10/E10,0) -> 0.95336041 | H10: =(E10*0.8)-F10 -> -1772891.9 | I10: =H10/$Q$2 -> -1772891.9 | J10: =(E10*0.86)-F10 -> -1079274.1 | K10: =J10/$Q$2 -> -1079274.1 | L10: =(E10*0.91)-F10 -> -501259.23 | M10: =L10/$Q$2 -> -501259.23 | N10: =(E10*0.96)-F10 -> 76755.618 | O10: =N10/$Q$2 -> 76755.618 | P10: =E10-F10 -> 539167.5 | Q10: =P10/$Q$2 -> 539167.5
A11: 8 | B11: M/S. Rasel Enterprise | C11: Khulna | D11: Faridpur | E11: 8615673.5 | F11: 8397885.5 | G11: =IFERROR(F11/E11,0) -> 0.97472188 | H11: =(E11*0.8)-F11 -> -1505346.7 | I11: =H11/$Q$2 -> -1505346.7 | J11: =(E11*0.86)-F11 -> -988406.28 | K11: =J11/$Q$2 -> -988406.28 | L11: =(E11*0.91)-F11 -> -557622.61 | M11: =L11/$Q$2 -> -557622.61 | N11: =(E11*0.96)-F11 -> -126838.93 | O11: =N11/$Q$2 -> -126838.93 | P11: =E11-F11 -> 217788.01 | Q11: =P11/$Q$2 -> 217788.01
A12: 9 | B12: Mridha Telecom | C12: Khulna | D12: Madaripur | E12: 5517099 | F12: 6113874.3 | G12: =IFERROR(F12/E12,0) -> 1.1081683 | H12: =(E12*0.8)-F12 -> -1700195 | I12: =H12/$Q$2 -> -1700195 | J12: =(E12*0.86)-F12 -> -1369169.1 | K12: =J12/$Q$2 -> -1369169.1 | L12: =(E12*0.91)-F12 -> -1093314.2 | M12: =L12/$Q$2 -> -1093314.2 | N12: =(E12*0.96)-F12 -> -817459.2 | O12: =N12/$Q$2 -> -817459.2 | P12: =E12-F12 -> -596775.24 | Q12: =P12/$Q$2 -> -596775.24
A13: 10 | B13: Toushi Mobile Showroom & Servicing | C13: Khulna | D13: Faridpur | E13: 4987063.1 | F13: 4752464.9 | G13: =IFERROR(F13/E13,0) -> 0.95295865 | H13: =(E13*0.8)-F13 -> -762814.43 | I13: =H13/$Q$2 -> -762814.43 | J13: =(E13*0.86)-F13 -> -463590.64 | K13: =J13/$Q$2 -> -463590.64 | L13: =(E13*0.91)-F13 -> -214237.49 | M13: =L13/$Q$2 -> -214237.49 | N13: =(E13*0.96)-F13 -> 35115.663 | O13: =N13/$Q$2 -> 35115.663 | P13: =E13-F13 -> 234598.19 | Q13: =P13/$Q$2 -> 234598.19
A14: 11 | B14: Winner Electronics | C14: Khulna | D14: Madaripur | E14: 6596269.9 | F14: 8441342.7 | G14: =IFERROR(F14/E14,0) -> 1.2797146 | H14: =(E14*0.8)-F14 -> -3164326.7 | I14: =H14/$Q$2 -> -3164326.7 | J14: =(E14*0.86)-F14 -> -2768550.5 | K14: =J14/$Q$2 -> -2768550.5 | L14: =(E14*0.91)-F14 -> -2438737 | M14: =L14/$Q$2 -> -2438737 | N14: =(E14*0.96)-F14 -> -2108923.5 | O14: =N14/$Q$2 -> -2108923.5 | P14: =E14-F14 -> -1845072.7 | Q14: =P14/$Q$2 -> -1845072.7
A15: 12 | B15: Biponon Communications | C15: Chattogram | D15: Cox's Bazar | E15: 4737117.3 | F15: 3832774.4 | G15: =IFERROR(F15/E15,0) -> 0.80909426 | H15: =(E15*0.8)-F15 -> -43080.583 | I15: =H15/$Q$2 -> -43080.583 | J15: =(E15*0.86)-F15 -> 241146.45 | K15: =J15/$Q$2 -> 241146.45 | L15: =(E15*0.91)-F15 -> 478002.32 | M15: =L15/$Q$2 -> 478002.32 | N15: =(E15*0.96)-F15 -> 714858.18 | O15: =N15/$Q$2 -> 714858.18 | P15: =E15-F15 -> 904342.87 | Q15: =P15/$Q$2 -> 904342.87
... A124: 121 | B124: Edison Electronics Ltd. | C124: Edison Electronics Limited | D124: Edison Electronics Ltd. | E124: 28437843 | F124: 28788610 | G124: =IFERROR(F124/E124,0) -> 1.0123345 | H124: =(E124*0.8)-F124 -> -6038335.9 | I124: =H124/$Q$2 -> -6038335.9 | J124: =(E124*0.86)-F124 -> -4332065.3 | K124: =J124/$Q$2 -> -4332065.3 | L124: =(E124*0.91)-F124 -> -2910173.2 | M124: =L124/$Q$2 -> -2910173.2 | N124: =(E124*0.96)-F124 -> -1488281.1 | O124: =N124/$Q$2 -> -1488281.1 | P124: =E124-F124 -> -350767.35 | Q124: =P124/$Q$2 -> -350767.35
A125: National Total | E125: =SUM(E4:E124) -> 1.5551967e+09 | F125: =SUM(F4:F124) -> 1.5568182e+09 | G125: =IFERROR(F125/E125,0) -> 1.0010426 | H125: =(E125*0.9)-F125 -> -1.5714113e+08 | I125: =H125/$Q$2 -> -1.5714113e+08 | J125: =(E125*0.85)-F125 -> -2.3490097e+08 | K125: =J125/$Q$2 -> -2.3490097e+08 | L125: =(E125*0.9)-F125 -> -1.5714113e+08 | M125: =L125/$Q$2 -> -1.5714113e+08 | N125: =(G125*0.9)-H125 -> 1.5714114e+08 | O125: =N125/$Q$2 -> 1.5714114e+08 | P125: =E125-F125 -> -1621462.6 | Q125: =P125/$Q$2 -> -1621462.6

Sheet Sheet2
A1: M/S. Karachi Store | B1: Barisal
A2: Toushi Mobile Showroom & Servicing | B2: Barisal
A3: Click Mobile Corner | B3: Barisal
A4: M/S Faiz Enterprise | B4: Barisal
A5: Zaman Electronics | B5: Barisal
A6: Mridha Telecom | B6: Barisal
A7: M/S. Rasel Enterprise | B7: Barisal
A8: M/S Saad Telecom | B8: Barisal
A9: Winner Electronics | B9: Barisal
A10: M/S. National Electronics | B10: Barisal
A11: Desh Link | B11: Barisal
A12: My Fone | B12: Barisal
... A122: Edison Electronics Ltd. | B122: Dhaka

Sheet Region Wise
A1: ='Dealer Wise'!B1 -> Up to 29.07.2020
A2: JULY'20 Back Margin Region Wise Value Achievement Status | M2: Remaining Days | N2: ='Dealer Wise'!Q2 -> 1
A3: Region | B3: Target JULY 2020 | C3: Achievement JULY 2020 | D3: Achievement % JULY 2020 | E3: Remaining for 80% | F3: Daily Required Rate for 80% | G3: Remaining for 86% | H3: Daily Required Rate for 86% | I3: Remaining for 91% | J3: Daily Required Rate for 91% | K3: Remaining for 96% | L3: Daily Required Rate for 96% | M3: Remaining for 100% | N3: Daily Required Rate for 100%
A4: Chattogram | B4: =SUMIFS('Dealer Wise'!E$4:E$124,'Dealer Wise'!$C$4:$C$124,'Region Wise'!$A4) -> 2.1660609e+08 | C4: =SUMIFS('Dealer Wise'!F$4:F$124,'Dealer Wise'!$C$4:$C$124,'Region Wise'!$A4) -> 2.2087745e+08 | D4: =C4/B4 -> 1.0197195 | E4: =(B4*0.8)-C4 -> -47592585 | F4: =E4/$N$2 -> -47592585 | G4: =(B4*0.86)-C4 -> -34596220 | H4: =G4/$N$2 -> -34596220 | I4: =(B4*0.91)-C4 -> -23765916 | J4: =I4/$N$2 -> -23765916 | K4: =(B4*0.96)-C4 -> -12935611 | L4: =K4/$N$2 -> -12935611 | M4: =B4-C4 -> -4271368 | N4: =M4/$N$2 -> -4271368
A5: Dhaka North | B5: =SUMIFS('Dealer Wise'!E$4:E$124,'Dealer Wise'!$C$4:$C$124,'Region Wise'!$A5) -> 3.5926242e+08 | C5: =SUMIFS('Dealer Wise'!F$4:F$124,'Dealer Wise'!$C$4:$C$124,'Region Wise'!$A5) -> 3.5254848e+08 | D5: =C5/B5 -> 0.9813119 | E5: =(B5*0.8)-C5 -> -65138551 | F5: =E5/$N$2 -> -65138551 | G5: =(B5*0.86)-C5 -> -43582806 | H5: =G5/$N$2 -> -43582806 | I5: =(B5*0.91)-C5 -> -25619685 | J5: =I5/$N$2 -> -25619685 | K5: =(B5*0.96)-C5 -> -7656564.2 | L5: =K5/$N$2 -> -7656564.2 | M5: =B5-C5 -> 6713932.5 | N5: =M5/$N$2 -> 6713932.5
A6: Dhaka South | B6: =SUMIFS('Dealer Wise'!E$4:E$124,'Dealer Wise'!$C$4:$C$124,'Region Wise'!$A6) -> 2.9160474e+08 | C6: =SUMIFS('Dealer Wise'!F$4:F$124,'Dealer Wise'!$C$4:$C$124,'Region Wise'!$A6) -> 2.774704e+08 | D6: =C6/B6 -> 0.95152912 | E6: =(B6*0.8)-C6 -> -44186611 | F6: =E6/$N$2 -> -44186611 | G6: =(B6*0.86)-C6 -> -26690326 | H6: =G6/$N$2 -> -26690326 | I6: =(B6*0.91)-C6 -> -12110089 | J6: =I6/$N$2 -> -12110089 | K6: =(B6*0.96)-C6 -> 2470148.1 | L6: =K6/$N$2 -> 2470148.1 | M6: =B6-C6 -> 14134338 | N6: =M6/$N$2 -> 14134338
A7: Khulna | B7: =SUMIFS('Dealer Wise'!E$4:E$124,'Dealer Wise'!$C$4:$C$124,'Region Wise'!$A7) -> 2.8003858e+08 | C7: =SUMIFS('Dealer Wise'!F$4:F$124,'Dealer Wise'!$C$4:$C$124,'Region Wise'!$A7) -> 2.8365235e+08 | D7: =C7/B7 -> 1.0129046 | E7: =(B7*0.8)-C7 -> -59621492 | F7: =E7/$N$2 -> -59621492 | G7: =(B7*0.86)-C7 -> -42819177 | H7: =G7/$N$2 -> -42819177 | I7: =(B7*0.91)-C7 -> -28817249 | J7: =I7/$N$2 -> -28817249 | K7: =(B7*0.96)-C7 -> -14815320 | L7: =K7/$N$2 -> -14815320 | M7: =B7-C7 -> -3613776.8 | N7: =M7/$N$2 -> -3613776.8
A8: Rajshahi | B8: =SUMIFS('Dealer Wise'!E$4:E$124,'Dealer Wise'!$C$4:$C$124,'Region Wise'!$A8) -> 2.0263939e+08 | C8: =SUMIFS('Dealer Wise'!F$4:F$124,'Dealer Wise'!$C$4:$C$124,'Region Wise'!$A8) -> 2.0372337e+08 | D8: =C8/B8 -> 1.0053493 | E8: =(B8*0.8)-C8 -> -41611863 | F8: =E8/$N$2 -> -41611863 | G8: =(B8*0.86)-C8 -> -29453499 | H8: =G8/$N$2 -> -29453499 | I8: =(B8*0.91)-C8 -> -19321530 | J8: =I8/$N$2 -> -19321530 | K8: =(B8*0.96)-C8 -> -9189561 | L8: =K8/$N$2 -> -9189561 | M8: =B8-C8 -> -1083985.6 | N8: =M8/$N$2 -> -1083985.6
A9: Rangpur | B9: =SUMIFS('Dealer Wise'!E$4:E$124,'Dealer Wise'!$C$4:$C$124,'Region Wise'!$A9) -> 1.7660767e+08 | C9: =SUMIFS('Dealer Wise'!F$4:F$124,'Dealer Wise'!$C$4:$C$124,'Region Wise'!$A9) -> 1.897575e+08 | D9: =C9/B9 -> 1.0744579 | E9: =(B9*0.8)-C9 -> -48471369 | F9: =E9/$N$2 -> -48471369 | G9: =(B9*0.86)-C9 -> -37874909 | H9: =G9/$N$2 -> -37874909 | I9: =(B9*0.91)-C9 -> -29044525 | J9: =I9/$N$2 -> -29044525 | K9: =(B9*0.96)-C9 -> -20214142 | L9: =K9/$N$2 -> -20214142 | M9: =B9-C9 -> -13149835 | N9: =M9/$N$2 -> -13149835
A10: National Total | B10: =SUM(B4:B9) -> 1.5267589e+09 | C10: =SUM(C4:C9) -> 1.5280296e+09 | D10: =C10/B10 -> 1.0008323 | E10: =SUM(E4:E9) -> -3.0662247e+08 | F10: =SUM(F4:F9) -> -3.0662247e+08 | G10: =SUM(G4:G9) -> -2.1501694e+08 | H10: =SUM(H4:H9) -> -2.1501694e+08 | I10: =SUM(I4:I9) -> -1.3867899e+08 | J10: =I10/$N$2 -> -1.3867899e+08 | K10: =SUM(K4:K9) -> -62341050 | L10: =K10/$N$2 -> -62341050 | M10: =SUM(M4:M9) -> -1270695.3 | N10: =M10/N2 -> -1270695.3

Sheet Zone Wise
B1: ='Dealer Wise'!B1 -> Up to 29.07.2020
A2: JULY'20 Back Margin Zone Wise Value Achievement Status | O2: Remaining Days | P2: ='Dealer Wise'!Q2 -> 1
A3: Sl. | B3: Region/ Cluster | C3: Dealer Zone | D3: Target JULY 2020 | E3: Achievement JULY 2020 | F3: Achievement % JULY 2020 | G3: Remaining for 80% | H3: Daily Required Rate for 80% | I3: Remaining for 86% | J3: Daily Required Rate for 86% | K3: Remaining for 91% | L3: Daily Required Rate for 91% | M3: Remaining for 96% | N3: Daily Required Rate for 96% | O3: Remaining for 100% | P3: Daily Required Rate for 100%
A4: 1 | B4: Chattogram | C4: Chandpur | D4: =SUMIFS('Dealer Wise'!E$4:E$124,'Dealer Wise'!$D$4:$D$124,'Zone Wise'!$C4) -> 35379916 | E4: =SUMIFS('Dealer Wise'!F$4:F$124,'Dealer Wise'!$D$4:$D$124,'Zone Wise'!$C4) -> 38795745 | F4: =E4/D4 -> 1.0965471 | G4: =(D4*0.8)-E4 -> -10491812 | H4: =G4/$P$2 -> -10491812 | I4: =(D4*0.86)-E4 -> -8369016.8 | J4: =I4/$P$2 -> -8369016.8 | K4: =(D4*0.91)-E4 -> -6600021 | L4: =K4/$P$2 -> -6600021 | M4: =(D4*0.96)-E4 -> -4831025.2 | N4: =M4/$P$2 -> -4831025.2 | O4: =D4-E4 -> -3415828.5 | P4: =O4/$P$2 -> -3415828.5
A5: 2 | B5: Chattogram | C5: Chattogram | D5: =SUMIFS('Dealer Wise'!E$4:E$124,'Dealer Wise'!$D$4:$D$124,'Zone Wise'!$C5) -> 58648182 | E5: =SUMIFS('Dealer Wise'!F$4:F$124,'Dealer Wise'!$D$4:$D$124,'Zone Wise'!$C5) -> 59858283 | F5: =E5/D5 -> 1.0206332 | G5: =(D5*0.8)-E5 -> -12939737 | H5: =G5/$P$2 -> -12939737 | I5: =(D5*0.86)-E5 -> -9420846.6 | J5: =I5/$P$2 -> -9420846.6 | K5: =(D5*0.91)-E5 -> -6488437.5 | L5: =K5/$P$2 -> -6488437.5 | M5: =(D5*0.96)-E5 -> -3556028.4 | N5: =M5/$P$2 -> -3556028.4 | O5: =D5-E5 -> -1210101.1 | P5: =O5/$P$2 -> -1210101.1
A6: 3 | B6: Chattogram | C6: Cox's Bazar | D6: =SUMIFS('Dealer Wise'!E$4:E$124,'Dealer Wise'!$D$4:$D$124,'Zone Wise'!$C6) -> 25677519 | E6: =SUMIFS('Dealer Wise'!F$4:F$124,'Dealer Wise'!$D$4:$D$124,'Zone Wise'!$C6) -> 23534429 | F6: =E6/D6 -> 0.91653827 | G6: =(D6*0.8)-E6 -> -2992413.6 | H6: =G6/$P$2 -> -2992413.6 | I6: =(D6*0.86)-E6 -> -1451762.4 | J6: =I6/$P$2 -> -1451762.4 | K6: =(D6*0.91)-E6 -> -167886.47 | L6: =K6/$P$2 -> -167886.47 | M6: =(D6*0.96)-E6 -> 1115989.5 | N6: =M6/$P$2 -> 1115989.5 | O6: =D6-E6 -> 2143090.3 | P6: =O6/$P$2 -> 2143090.3
A7: 4 | B7: Chattogram | C7: Cumilla | D7: =SUMIFS('Dealer Wise'!E$4:E$124,'Dealer Wise'!$D$4:$D$124,'Zone Wise'!$C7) -> 31278947 | E7: =SUMIFS('Dealer Wise'!F$4:F$124,'Dealer Wise'!$D$4:$D$124,'Zone Wise'!$C7) -> 31008905 | F7: =E7/D7 -> 0.99136664 | G7: =(D7*0.8)-E7 -> -5985747.1 | H7: =G7/$P$2 -> -5985747.1 | I7: =(D7*0.86)-E7 -> -4109010.2 | J7: =I7/$P$2 -> -4109010.2 | K7: =(D7*0.91)-E7 -> -2545062.9 | L7: =K7/$P$2 -> -2545062.9 | M7: =(D7*0.96)-E7 -> -981115.54 | N7: =M7/$P$2 -> -981115.54 | O7: =D7-E7 -> 270042.35 | P7: =O7/$P$2 -> 270042.35
A8: 5 | B8: Chattogram | C8: Noakhali | D8: =SUMIFS('Dealer Wise'!E$4:E$124,'Dealer Wise'!$D$4:$D$124,'Zone Wise'!$C8) -> 38448332 | E8: =SUMIFS('Dealer Wise'!F$4:F$124,'Dealer Wise'!$D$4:$D$124,'Zone Wise'!$C8) -> 42316018 | F8: =E8/D8 -> 1.1005944 | G8: =(D8*0.8)-E8 -> -11557352 | H8: =G8/$P$2 -> -11557352 | I8: =(D8*0.86)-E8 -> -9250452.4 | J8: =I8/$P$2 -> -9250452.4 | K8: =(D8*0.91)-E8 -> -7328035.8 | L8: =K8/$P$2 -> -7328035.8 | M8: =(D8*0.96)-E8 -> -5405619.2 | N8: =M8/$P$2 -> -5405619.2 | O8: =D8-E8 -> -3867685.9 | P8: =O8/$P$2 -> -3867685.9
A9: 6 | B9: Chattogram | C9: Rangamati | D9: =SUMIFS('Dealer Wise'!E$4:E$124,'Dealer Wise'!$D$4:$D$124,'Zone Wise'!$C9) -> 27173189 | E9: =SUMIFS('Dealer Wise'!F$4:F$124,'Dealer Wise'!$D$4:$D$124,'Zone Wise'!$C9) -> 25364074 | F9: =E9/D9 -> 0.9334228 | G9: =(D9*0.8)-E9 -> -3625522.8 | H9: =G9/$P$2 -> -3625522.8 | I9: =(D9*0.86)-E9 -> -1995131.5 | J9: =I9/$P$2 -> -1995131.5 | K9: =(D9*0.91)-E9 -> -636472.07 | L9: =K9/$P$2 -> -636472.07 | M9: =(D9*0.96)-E9 -> 722187.36 | N9: =M9/$P$2 -> 722187.36 | O9: =D9-E9 -> 1809114.9 | P9: =O9/$P$2 -> 1809114.9
A10: 7 | B10: Dhaka North | C10: Gazipur | D10: =SUMIFS('Dealer Wise'!E$4:E$124,'Dealer Wise'!$D$4:$D$124,'Zone Wise'!$C10) -> 57191625 | E10: =SUMIFS('Dealer Wise'!F$4:F$124,'Dealer Wise'!$D$4:$D$124,'Zone Wise'!$C10) -> 60343253 | F10: =E10/D10 -> 1.0551065 | G10: =(D10*0.8)-E10 -> -14589953 | H10: =G10/$P$2 -> -14589953 | I10: =(D10*0.86)-E10 -> -11158455 | J10: =I10/$P$2 -> -11158455 | K10: =(D10*0.91)-E10 -> -8298874 | L10: =K10/$P$2 -> -8298874 | M10: =(D10*0.96)-E10 -> -5439292.7 | N10: =M10/$P$2 -> -5439292.7 | O10: =D10-E10 -> -3151627.7 | P10: =O10/$P$2 -> -3151627.7
A11: 8 | B11: Dhaka North | C11: Gulshan | D11: =SUMIFS('Dealer Wise'!E$4:E$124,'Dealer Wise'!$D$4:$D$124,'Zone Wise'!$C11) -> 30804280 | E11: =SUMIFS('Dealer Wise'!F$4:F$124,'Dealer Wise'!$D$4:$D$124,'Zone Wise'!$C11) -> 21125124 | F11: =E11/D11 -> 0.68578533 | G11: =(D11*0.8)-E11 -> 3518300.7 | H11: =G11/$P$2 -> 3518300.7 | I11: =(D11*0.86)-E11 -> 5366557.5 | J11: =I11/$P$2 -> 5366557.5 | K11: =(D11*0.91)-E11 -> 6906771.5 | L11: =K11/$P$2 -> 6906771.5 | M11: =(D11*0.96)-E11 -> 8446985.5 | N11: =M11/$P$2 -> 8446985.5 | O11: =D11-E11 -> 9679156.7 | P11: =O11/$P$2 -> 9679156.7
A12: 9 | B12: Dhaka North | C12: Jamalpur | D12: =SUMIFS('Dealer Wise'!E$4:E$124,'Dealer Wise'!$D$4:$D$124,'Zone Wise'!$C12) -> 46934978 | E12: =SUMIFS('Dealer Wise'!F$4:F$124,'Dealer Wise'!$D$4:$D$124,'Zone Wise'!$C12) -> 40412458 | F12: =E12/D12 -> 0.86103073 | G12: =(D12*0.8)-E12 -> -2864476.2 | H12: =G12/$P$2 -> -2864476.2 | I12: =(D12*0.86)-E12 -> -48377.514 | J12: =I12/$P$2 -> -48377.514 | K12: =(D12*0.91)-E12 -> 2298371.4 | L12: =K12/$P$2 -> 2298371.4 | M12: =(D12*0.96)-E12 -> 4645120.2 | N12: =M12/$P$2 -> 4645120.2 | O12: =D12-E12 -> 6522519.4 | P12: =O12/$P$2 -> 6522519.4
A13: 10 | B13: Dhaka North | C13: Kishoreganj | D13: =SUMIFS('Dealer Wise'!E$4:E$124,'Dealer Wise'!$D$4:$D$124,'Zone Wise'!$C13) -> 41370460 | E13: =SUMIFS('Dealer Wise'!F$4:F$124,'Dealer Wise'!$D$4:$D$124,'Zone Wise'!$C13) -> 43217125 | F13: =E13/D13 -> 1.0446373 | G13: =(D13*0.8)-E13 -> -10120757 | H13: =G13/$P$2 -> -10120757 | I13: =(D13*0.86)-E13 -> -7638529.3 | J13: =I13/$P$2 -> -7638529.3 | K13: =(D13*0.91)-E13 -> -5570006.3 | L13: =K13/$P$2 -> -5570006.3 | M13: =(D13*0.96)-E13 -> -3501483.3 | N13: =M13/$P$2 -> -3501483.3 | O13: =D13-E13 -> -1846664.9 | P13: =O13/$P$2 -> -1846664.9
A14: 11 | B14: Dhaka North | C14: Mawna | D14: =SUMIFS('Dealer Wise'!E$4:E$124,'Dealer Wise'!$D$4:$D$124,'Zone Wise'!$C14) -> 26256836 | E14: =SUMIFS('Dealer Wise'!F$4:F$124,'Dealer Wise'!$D$4:$D$124,'Zone Wise'!$C14) -> 25199329 | F14: =E14/D14 -> 0.95972451 | G14: =(D14*0.8)-E14 -> -4193860.1 | H14: =G14/$P$2 -> -4193860.1 | I14: =(D14*0.86)-E14 -> -2618450 | J14: =I14/$P$2 -> -2618450 | K14: =(D14*0.91)-E14 -> -1305608.2 | L14: =K14/$P$2 -> -1305608.2 | M14: =(D14*0.96)-E14 -> 7233.5511 | N14: =M14/$P$2 -> 7233.5511 | O14: =D14-E14 -> 1057507 | P14: =O14/$P$2 -> 1057507
A15: 12 | B15: Dhaka North | C15: Mirpur | D15: =SUMIFS('Dealer Wise'!E$4:E$124,'Dealer Wise'!$D$4:$D$124,'Zone Wise'!$C15) -> 38381677 | E15: =SUMIFS('Dealer Wise'!F$4:F$124,'Dealer Wise'!$D$4:$D$124,'Zone Wise'!$C15) -> 39108981 | F15: =E15/D15 -> 1.0189493 | G15: =(D15*0.8)-E15 -> -8403639.5 | H15: =G15/$P$2 -> -8403639.5 | I15: =(D15*0.86)-E15 -> -6100738.9 | J15: =I15/$P$2 -> -6100738.9 | K15: =(D15*0.91)-E15 -> -4181655 | L15: =K15/$P$2 -> -4181655 | M15: =(D15*0.96)-E15 -> -2262571.1 | N15: =M15/$P$2 -> -2262571.1 | O15: =D15-E15 -> -727304.04 | P15: =O15/$P$2 -> -727304.04
... A44: 41 | B44: Rangpur | C44: Thakurgaon | D44: =SUMIFS('Dealer Wise'!E$4:E$124,'Dealer Wise'!$D$4:$D$124,'Zone Wise'!$C44) -> 32779875 | E44: =SUMIFS('Dealer Wise'!F$4:F$124,'Dealer Wise'!$D$4:$D$124,'Zone Wise'!$C44) -> 35366336 | F44: =E44/D44 -> 1.0789039 | G44: =(D44*0.8)-E44 -> -9142436.4 | H44: =G44/$P$2 -> -9142436.4 | I44: =(D44*0.86)-E44 -> -7175643.9 | J44: =I44/$P$2 -> -7175643.9 | K44: =(D44*0.91)-E44 -> -5536650.2 | L44: =K44/$P$2 -> -5536650.2 | M44: =(D44*0.96)-E44 -> -3897656.4 | N44: =M44/$P$2 -> -3897656.4 | O44: =D44-E44 -> -2586461.4 | P44: =O44/$P$2 -> -2586461.4
A45: National Total | D45: =SUM(D4:D44) -> 1.5267589e+09 | E45: =SUM(E4:E44) -> 1.5280296e+09 | F45: =E45/D45 -> 1.0008323 | G45: =SUM(G4:G44) -> -3.0662247e+08 | H45: =SUM(H4:H44) -> -3.0662247e+08 | I45: =SUM(I4:I44) -> -2.1501694e+08 | J45: =SUM(J4:J44) -> -2.1501694e+08 | K45: =SUM(K4:K44) -> -1.3867899e+08 | L45: =SUM(L4:L44) -> -1.3867899e+08 | M45: =SUM(M4:M44) -> -62341050 | N45: =SUM(N4:N44) -> -62341050 | ... P45: =SUM(P4:P44) -> -1270695.3

Sheet DSR
A4: SL No. | B4: Dealer Name | C4: Region | D4: DSR ID | E4: DSR Name | F4: DSR wise Back Margin till 28 JULY'20 | L4: Weightage | N4: Total (100%)
F5: JULY Target | H5: JULY Achievement | J5: Achievement
F6: Quantity | G6: Value | H6: Quantity | I6: Value | J6: Quantity | K6: Value | L6: Quantity (30%) | M6: Value (70%)
A7: 1 | B7: M/S Sholav Bitan | C7: Chattogram | D7: DSR-0692 | E7: Md Juwel | F7: 7317 | G7: 12505346 | H7: 10719 | I7: 15040435 | J7: =IFERROR(H7/F7,0) -> 1.4649446 | K7: =IFERROR(I7/G7,0) -> 1.2027204 | L7: =IF((J7*0.3)>30%,30%,(J7*0.3)) -> 0.3 | M7: =IF((K7*0.7)>70%,70%,(K7*0.7)) -> 0.7 | N7: =L7+M7 -> 1
A8: 2 | B8: M/S Sholav Bitan | C8: Chattogram | D8: DSR-0691 | E8: Md. Muslim | F8: 6671 | G8: 11407419 | H8: 7056 | I8: 10627700 | J8: =IFERROR(H8/F8,0) -> 1.0577125 | K8: =IFERROR(I8/G8,0) -> 0.93164804 | L8: =IF((J8*0.3)>30%,30%,(J8*0.3)) -> 0.3 | M8: =IF((K8*0.7)>70%,70%,(K8*0.7)) -> 0.65215363 | N8: =L8+M8 -> 0.95215363
A9: 3 | B9: M/S Sholav Bitan | C9: Chattogram | D9: DSR-0693 | E9: Md.Nipon | F9: 430 | G9: 737873.32 | H9: 454 | I9: 790085 | J9: =IFERROR(H9/F9,0) -> 1.055814 | K9: =IFERROR(I9/G9,0) -> 1.0707597 | L9: =IF((J9*0.3)>30%,30%,(J9*0.3)) -> 0.3 | M9: =IF((K9*0.7)>70%,70%,(K9*0.7)) -> 0.7 | N9: =L9+M9 -> 1
A10: 4 | B10: M/S Sholav Bitan | C10: Chattogram | D10: DSR-0658 | E10: Mohmmad Hasan | F10: 2588 | G10: 4434949.7 | H10: 2050 | I10: 3658490 | J10: =IFERROR(H10/F10,0) -> 0.79211747 | K10: =IFERROR(I10/G10,0) -> 0.82492256 | L10: =IF((J10*0.3)>30%,30%,(J10*0.3)) -> 0.23763524 | M10: =IF((K10*0.7)>70%,70%,(K10*0.7)) -> 0.57744579 | N10: =L10+M10 -> 0.81508103
A11: 5 | B11: M/S Sholav Bitan | C11: Chattogram | D11: DSR-0695 | E11: Md. Nahid | F11: 2588 | G11: 4434949.7 | H11: 678 | I11: 1231890 | J11: =IFERROR(H11/F11,0) -> 0.26197836 | K11: =IFERROR(I11/G11,0) -> 0.27776866 | L11: =IF((J11*0.3)>30%,30%,(J11*0.3)) -> 0.078593509 | M11: =IF((K11*0.7)>70%,70%,(K11*0.7)) -> 0.19443806 | N11: =L11+M11 -> 0.27303157
A12: 6 | B12: M/S Sholav Bitan | C12: Chattogram | D12: DSR-0659 | E12: Md. Nurul Alam | F12: 1938 | G12: 3312560.5 | H12: 530 | I12: 1107535 | J12: =IFERROR(H12/F12,0) -> 0.27347781 | K12: =IFERROR(I12/G12,0) -> 0.33434408 | L12: =IF((J12*0.3)>30%,30%,(J12*0.3)) -> 0.082043344 | M12: =IF((K12*0.7)>70%,70%,(K12*0.7)) -> 0.23404086 | N12: =L12+M12 -> 0.3160842
A13: 7 | B13: Sibgat Telecom | C13: Chattogram | D13: DSR-0674 | E13: H.M. Arshad | F13: 3320 | G13: 5677341.2 | H13: 3932 | I13: 6676100 | J13: =IFERROR(H13/F13,0) -> 1.1843373 | K13: =IFERROR(I13/G13,0) -> 1.1759202 | L13: =IF((J13*0.3)>30%,30%,(J13*0.3)) -> 0.3 | M13: =IF((K13*0.7)>70%,70%,(K13*0.7)) -> 0.7 | N13: =L13+M13 -> 1
A14: 8 | B14: Sibgat Telecom | C14: Chattogram | D14: DSR-0663 | E14: Ariful Hoque | F14: 1551 | G14: 2652021.2 | H14: 1151 | I14: 2262955 | J14: =IFERROR(H14/F14,0) -> 0.74210187 | K14: =IFERROR(I14/G14,0) -> 0.85329446 | L14: =IF((J14*0.3)>30%,30%,(J14*0.3)) -> 0.22263056 | M14: =IF((K14*0.7)>70%,70%,(K14*0.7)) -> 0.59730612 | N14: =L14+M14 -> 0.81993668
A15: 9 | B15: Sibgat Telecom | C15: Chattogram | D15: DSR-0675 | E15: Rahatul Islam | F15: 3156 | G15: 5391822.8 | H15: 3483 | I15: 5660145 | J15: =IFERROR(H15/F15,0) -> 1.1036122 | K15: =IFERROR(I15/G15,0) -> 1.0497646 | L15: =IF((J15*0.3)>30%,30%,(J15*0.3)) -> 0.3 | M15: =IF((K15*0.7)>70%,70%,(K15*0.7)) -> 0.7 | N15: =L15+M15 -> 1
A16: 10 | B16: Sibgat Telecom | C16: Chattogram | D16: DSR-0118 | E16: Md. Tareq Rahman | F16: 997 | G16: 1704560.5 | H16: 693 | I16: 986845 | J16: =IFERROR(H16/F16,0) -> 0.69508526 | K16: =IFERROR(I16/G16,0) -> 0.57894396 | L16: =IF((J16*0.3)>30%,30%,(J16*0.3)) -> 0.20852558 | M16: =IF((K16*0.7)>70%,70%,(K16*0.7)) -> 0.40526077 | N16: =L16+M16 -> 0.61378635
A17: 11 | B17: Sibgat Telecom | C17: Chattogram | D17: DSR-0678 | E17: Jahidul Islam | F17: 891 | G17: 1533349.1 | H17: 489 | I17: 920220 | J17: =IFERROR(H17/F17,0) -> 0.54882155 | K17: =IFERROR(I17/G17,0) -> 0.60013732 | L17: =IF((J17*0.3)>30%,30%,(J17*0.3)) -> 0.16464646 | M17: =IF((K17*0.7)>70%,70%,(K17*0.7)) -> 0.42009612 | N17: =L17+M17 -> 0.58474259
A18: 12 | B18: Sibgat Telecom | C18: Chattogram | D18: DSR-0677 | E18: Kazi Mohammad Azimuddin | F18: 1162 | G18: 1988441.8 | H18: 1055 | I18: 1824785 | J18: =IFERROR(H18/F18,0) -> 0.90791738 | K18: =IFERROR(I18/G18,0) -> 0.91769595 | L18: =IF((J18*0.3)>30%,30%,(J18*0.3)) -> 0.27237522 | M18: =IF((K18*0.7)>70%,70%,(K18*0.7)) -> 0.64238716 | N18: =L18+M18 -> 0.91476238
... A215: 209 | B215: Nishat Telecom | C215: Dhaka South | D215: DSR-0150 | E215: Md. Kawsar | F215: 1322 | G215: 1542264.3 | H215: 633 | I215: 1140050 | J215: =IFERROR(H215/F215,0) -> 0.47881997 | K215: =IFERROR(I215/G215,0) -> 0.73920532 | L215: =IF((J215*0.3)>30%,30%,(J215*0.3)) -> 0.14364599 | M215: =IF((K215*0.7)>70%,70%,(K215*0.7)) -> 0.51744373 | N215: =L215+M215 -> 0.66108972
A216: 210 | B216: Taj Telecom | C216: Dhaka South | D216: DSR-0023 | E216: Md. Mosaddek Billah | F216: 1697 | G216: 2448383.6 | H216: #N/A | I216: #N/A | J216: =IFERROR(H216/F216,0) -> 0 | K216: =IFERROR(I216/G216,0) -> 0 | L216: =IF((J216*0.3)>30%,30%,(J216*0.3)) -> 0 | M216: =IF((K216*0.7)>70%,70%,(K216*0.7)) -> 0 | N216: =L216+M216 -> 0
A217: 211 | B217: Taj Telecom | C217: Dhaka South | D217: DSR-0048 | E217: Md. Asif Talukdar | F217: 2233 | G217: 5762639.4 | H217: 300 | I217: 1950990 | J217: =IFERROR(H217/F217,0) -> 0.13434841 | K217: =IFERROR(I217/G217,0) -> 0.33855841 | L217: =IF((J217*0.3)>30%,30%,(J217*0.3)) -> 0.040304523 | M217: =IF((K217*0.7)>70%,70%,(K217*0.7)) -> 0.23699088 | N217: =L217+M217 -> 0.27729541
A218: 212 | B218: Anika Traders | C218: Dhaka South | D218: DSR-0257 | E218: Rabbi | F218: 1463 | G218: 3284382.3 | H218: 1182 | I218: 2644560 | J218: =IFERROR(H218/F218,0) -> 0.80792891 | K218: =IFERROR(I218/G218,0) -> 0.8051925 | L218: =IF((J218*0.3)>30%,30%,(J218*0.3)) -> 0.24237867 | M218: =IF((K218*0.7)>70%,70%,(K218*0.7)) -> 0.56363475 | N218: =L218+M218 -> 0.80601342
A219: 213 | B219: Anika Traders | C219: Dhaka South | D219: DSR-0653 | E219: Hasan Ali Kahn | F219: 973 | G219: 2175122 | H219: 918 | I219: 1246070 | J219: =IFERROR(H219/F219,0) -> 0.94347379 | K219: =IFERROR(I219/G219,0) -> 0.57287361 | L219: =IF((J219*0.3)>30%,30%,(J219*0.3)) -> 0.28304214 | M219: =IF((K219*0.7)>70%,70%,(K219*0.7)) -> 0.40101152 | N219: =L219+M219 -> 0.68405366
A220: 214 | B220: Anika Traders | C220: Dhaka South | D220: DSR-0267 | E220: Faruk Khan | F220: 1050 | G220: 2354975.6 | H220: 1013 | I220: 1515015 | J220: =IFERROR(H220/F220,0) -> 0.9647619 | K220: =IFERROR(I220/G220,0) -> 0.64332512 | L220: =IF((J220*0.3)>30%,30%,(J220*0.3)) -> 0.28942857 | M220: =IF((K220*0.7)>70%,70%,(K220*0.7)) -> 0.45032759 | N220: =L220+M220 -> 0.73975616
A221: 215 | B221: One Telecom | C221: Dhaka South | D221: DSR-0014 | E221: Md. Sofiullah | F221: 3866 | G221: 6216321 | H221: 7252 | I221: 8372400 | J221: =IFERROR(H221/F221,0) -> 1.8758407 | K221: =IFERROR(I221/G221,0) -> 1.3468416 | L221: =IF((J221*0.3)>30%,30%,(J221*0.3)) -> 0.3 | M221: =IF((K221*0.7)>70%,70%,(K221*0.7)) -> 0.7 | N221: =L221+M221 -> 1
A222: 216 | B222: One Telecom | C222: Dhaka South | D222: DSR-0085 | E222: Md.Kawser Molla | F222: 2500 | G222: 4027518.2 | H222: 1181 | I222: 2451770 | J222: =IFERROR(H222/F222,0) -> 0.4724 | K222: =IFERROR(I222/G222,0) -> 0.60875454 | L222: =IF((J222*0.3)>30%,30%,(J222*0.3)) -> 0.14172 | M222: =IF((K222*0.7)>70%,70%,(K222*0.7)) -> 0.42612818 | N222: =L222+M222 -> 0.56784818
A223: 217 | B223: One Telecom | C223: Dhaka South | D223: DSR-0063 | E223: Md. Ariful Islam | F223: 3781 | G223: 6082276.7 | H223: 1726 | I223: 4800975 | J223: =IFERROR(H223/F223,0) -> 0.45649299 | K223: =IFERROR(I223/G223,0) -> 0.78933847 | L223: =IF((J223*0.3)>30%,30%,(J223*0.3)) -> 0.1369479 | M223: =IF((K223*0.7)>70%,70%,(K223*0.7)) -> 0.55253693 | N223: =L223+M223 -> 0.68948483
A224: 218 | B224: One Telecom | C224: Dhaka South | D224: DSR-0039 | E224: Md. Mahfuzur Rahman Masum | F224: 1041 | G224: 1685389.2 | H224: 781 | I224: 1312325 | J224: =IFERROR(H224/F224,0) -> 0.75024015 | K224: =IFERROR(I224/G224,0) -> 0.77864802 | L224: =IF((J224*0.3)>30%,30%,(J224*0.3)) -> 0.22507205 | M224: =IF((K224*0.7)>70%,70%,(K224*0.7)) -> 0.54505361 | N224: =L224+M224 -> 0.77012566
A225: 219 | B225: One Telecom | C225: Dhaka South | D225: DSR-0119 | E225: Sirajul Islam (Nayan) | F225: 2762 | G225: 4444741 | H225: 4404 | I225: 5810580 | J225: =IFERROR(H225/F225,0) -> 1.5944967 | K225: =IFERROR(I225/G225,0) -> 1.3072933 | L225: =IF((J225*0.3)>30%,30%,(J225*0.3)) -> 0.3 | M225: =IF((K225*0.7)>70%,70%,(K225*0.7)) -> 0.7 | N225: =L225+M225 -> 1
A226: 220 | B226: One Telecom, Jatrabari | C226: Dhaka South | D226: DSR-0134 | E226: Md. Toukir | F226: 1045 | G226: 1776822.4 | H226: 1325 | I226: 1730900 | J226: =IFERROR(H226/F226,0) -> 1.2679426 | K226: =IFERROR(I226/G226,0) -> 0.97415476 | L226: =IF((J226*0.3)>30%,30%,(J226*0.3)) -> 0.3 | M226: =IF((K226*0.7)>70%,70%,(K226*0.7)) -> 0.68190833 | N226: =L226+M226 -> 0.98190833
A227: 221 | B227: One Telecom, Jatrabari | C227: Dhaka South | D227: DSR-0145 | E227: Ashiq Ahmed | F227: 1763 | G227: 3004239.6 | H227: 1680 | I227: 2969975 | J227: =IFERROR(H227/F227,0) -> 0.95292116 | K227: =IFERROR(I227/G227,0) -> 0.98859459 | L227: =IF((J227*0.3)>30%,30%,(J227*0.3)) -> 0.28587635 | M227: =IF((K227*0.7)>70%,70%,(K227*0.7)) -> 0.69201622 | N227: =L227+M227 -> 0.97789256
A228: 222 | B228: One Telecom, Jatrabari | C228: Dhaka South | D228: DSR-0139 | E228: Faysal Ahmed | F228: 1128 | G228: 1924614.9 | H228: 840 | I228: 1766720 | J228: =IFERROR(H228/F228,0) -> 0.74468085 | K228: =IFERROR(I228/G228,0) -> 0.91796028 | L228: =IF((J228*0.3)>30%,30%,(J228*0.3)) -> 0.22340426 | M228: =IF((K228*0.7)>70%,70%,(K228*0.7)) -> 0.64257219 | N228: =L228+M228 -> 0.86597645
... A536: 530 | B536: Feroz Telecom | C536: Rangpur | D536: DSR-0253 | E536: Mr. Salim Iqbal | F536: 2568 | G536: 4303997.5 | H536: 3166 | I536: 4974315 | J536: =IFERROR(H536/F536,0) -> 1.232866 | K536: =IFERROR(I536/G536,0) -> 1.155743 | L536: =IF((J536*0.3)>30%,30%,(J536*0.3)) -> 0.3 | M536: =IF((K536*0.7)>70%,70%,(K536*0.7)) -> 0.7 | N536: =L536+M536 -> 1

Sheet JAN+FEB+MAR+MAY+JUNE
B1: Q Achivment'20
AB2: Days | AC2: ='Dealer Wise'!Q2 -> 1
A3: SL No. | B3: Dealer Name | C3: Region/ Cluster | D3: Dealer Zone | E3: JAN'20 | I3: FEB'20 | M3: MAR'20 | Q3: April & May'20 | U3: JUNE'20 | Y3: Q1-2020 | AC3: Per Day
E4: Target | F4: Achievement | G4: % | H4: Score 90% | I4: Target | J4: Achievement | K4: % | L4: Score 90% | M4: Target | N4: Achievement | O4: % | P4: Score 90% | Q4: Target | R4: Achievement | S4: % | T4: Score 90% | U4: Target | V4: Achievement | W4: % | X4: Score 90% | Y4: Q1 Target | Z4: Q1 Achievement | AA4: Q1% | AB4: Remaining
A5: 1 | B5: MM Communication | C5: Dhaka North | D5: Uttara | E5: 13946603 | F5: 15266103 | G5: =IFERROR(F5/E5,0) -> 1.0946108 | H5: =IF(G5>=89.5%,90%,0%) -> 0.9 | I5: 13445482 | J5: 12266706 | K5: =IFERROR(J5/I5,0) -> 0.9123292 | L5: =IF(K5>=89.5%,90%,0%) -> 0.9 | M5: 12846534 | N5: 5541285.7 | O5: =IFERROR(N5/M5,0) -> 0.4313448 | P5: =IF(O5>=89.5%,90%,0%) -> 0 | Q5: 10231115 | R5: 11595518 | S5: =IFERROR(R5/Q5,0) -> 1.1333582 | T5: =IF(S5>=89.5%,90%,0%) -> 0.9 | U5: 15167336 | V5: =VLOOKUP(B5,'Dealer Wise'!B4:F124,5,0) -> 17010991 | W5: =IFERROR(V5/U5,0) -> 1.1215543 | X5: =IF(W5>=89.5%,90%,0%) -> 0.9 | Y5: =E5+I5+M5+Q5+U5 -> 65637071 | Z5: =F5+J5+N5+R5+V5 -> 61680603 | AA5: =IFERROR(Z5/Y5,0) -> 0.93972205 | AB5: =Y5-M5:N126A5 -> #NAME? | AC5: =AB5/AC$2 -> #NAME?
A6: 2 | B6: Shore Distribution | C6: Dhaka North | D6: Savar | E6: 12566633 | F6: 12798336 | G6: =IFERROR(F6/E6,0) -> 1.018438 | H6: =IF(G6>=89.5%,90%,0%) -> 0.9 | I6: 11946061 | J6: 10892992 | K6: =IFERROR(J6/I6,0) -> 0.91184798 | L6: =IF(K6>=89.5%,90%,0%) -> 0.9 | M6: 12036003 | N6: 3688918.8 | O6: =IFERROR(N6/M6,0) -> 0.30649036 | P6: =IF(O6>=89.5%,90%,0%) -> 0 | Q6: 8468919.1 | R6: 11694244 | S6: =IFERROR(R6/Q6,0) -> 1.3808426 | T6: =IF(S6>=89.5%,90%,0%) -> 0.9 | U6: 14973802 | V6: =VLOOKUP(B6,'Dealer Wise'!B5:F125,5,0) -> 13628906 | W6: =IFERROR(V6/U6,0) -> 0.9101834 | X6: =IF(W6>=89.5%,90%,0%) -> 0.9 | Y6: =E6+I6+M6+Q6+U6 -> 59991418 | Z6: =F6+J6+N6+R6+V6 -> 52703398 | AA6: =IFERROR(Z6/Y6,0) -> 0.87851562 | AB6: =Y6-Z6 -> 7288020.4 | AC6: =AB6/AC$2 -> 7288020.4
A7: 3 | B7: Saif Telecom | C7: Dhaka South | D7: Dhanmondi | E7: 13251519 | F7: 13461503 | G7: =IFERROR(F7/E7,0) -> 1.0158461 | H7: =IF(G7>=89.5%,90%,0%) -> 0.9 | I7: 13373096 | J7: 10896642 | K7: =IFERROR(J7/I7,0) -> 0.81481824 | L7: =IF(K7>=89.5%,90%,0%) -> 0 | M7: 13961722 | N7: 6680595.8 | O7: =IFERROR(N7/M7,0) -> 0.4784937 | P7: =IF(O7>=89.5%,90%,0%) -> 0 | Q7: 10636827 | R7: 372471.29 | S7: =IFERROR(R7/Q7,0) -> 0.035017144 | T7: =IF(S7>=89.5%,90%,0%) -> 0 | U7: 10971048 | V7: =VLOOKUP(B7,'Dealer Wise'!B6:F126,5,0) -> 16853739 | W7: =IFERROR(V7/U7,0) -> 1.5362014 | X7: =IF(W7>=89.5%,90%,0%) -> 0.9 | Y7: =E7+I7+M7+Q7+U7 -> 62194211 | Z7: =F7+J7+N7+R7+V7 -> 48264951 | AA7: =IFERROR(Z7/Y7,0) -> 0.77603607 | AB7: =Y7-Z7 -> 13929260 | AC7: =AB7/AC$2 -> 13929260
A8: 4 | B8: Nabil Enterprise | C8: Dhaka North | D8: Gulshan | E8: 24518114 | F8: 24552383 | G8: =IFERROR(F8/E8,0) -> 1.0013977 | H8: =IF(G8>=89.5%,90%,0%) -> 0.9 | I8: 25762885 | J8: 25768230 | K8: =IFERROR(J8/I8,0) -> 1.0002075 | L8: =IF(K8>=89.5%,90%,0%) -> 0.9 | M8: 27386124 | N8: 4459056.4 | O8: =IFERROR(N8/M8,0) -> 0.16282174 | P8: =IF(O8>=89.5%,90%,0%) -> 0 | Q8: 15571528 | R8: 23363649 | S8: =IFERROR(R8/Q8,0) -> 1.5004082 | T8: =IF(S8>=89.5%,90%,0%) -> 0.9 | U8: 31611266 | V8: =VLOOKUP(B8,'Dealer Wise'!B7:F127,5,0) -> 21125124 | W8: =IFERROR(V8/U8,0) -> 0.66827832 | X8: =IF(W8>=89.5%,90%,0%) -> 0 | Y8: =E8+I8+M8+Q8+U8 -> 1.2484992e+08 | Z8: =F8+J8+N8+R8+V8 -> 99268442 | AA8: =IFERROR(Z8/Y8,0) -> 0.79510219 | AB8: =Y8-Z8 -> 25581475 | AC8: =AB8/AC$2 -> 25581475
A9: 5 | B9: TM Communication | C9: Dhaka North | D9: Uttara | E9: 14165697 | F9: 14204736 | G9: =IFERROR(F9/E9,0) -> 1.002756 | H9: =IF(G9>=89.5%,90%,0%) -> 0.9 | I9: 15542888 | J9: 12513226 | K9: =IFERROR(J9/I9,0) -> 0.80507731 | L9: =IF(K9>=89.5%,90%,0%) -> 0 | M9: 15879126 | N9: 6961879.8 | O9: =IFERROR(N9/M9,0) -> 0.43842967 | P9: =IF(O9>=89.5%,90%,0%) -> 0 | Q9: 12896058 | R9: 12473873 | S9: =IFERROR(R9/Q9,0) -> 0.96726247 | T9: =IF(S9>=89.5%,90%,0%) -> 0.9 | U9: 15628878 | V9: =VLOOKUP(B9,'Dealer Wise'!B8:F128,5,0) -> 18134040 | W9: =IFERROR(V9/U9,0) -> 1.1602906 | X9: =IF(W9>=89.5%,90%,0%) -> 0.9 | Y9: =E9+I9+M9+Q9+U9 -> 74112646 | Z9: =F9+J9+N9+R9+V9 -> 64287756 | AA9: =IFERROR(Z9/Y9,0) -> 0.86743301 | AB9: =Y9-Z9 -> 9824890.5 | AC9: =AB9/AC$2 -> 9824890.5
A10: 6 | B10: Mobile House | C10: Dhaka North | D10: Mirpur | E10: 24534222 | F10: 22435448 | G10: =IFERROR(F10/E10,0) -> 0.91445526 | H10: =IF(G10>=89.5%,90%,0%) -> 0.9 | I10: 25134354 | J10: 23636531 | K10: =IFERROR(J10/I10,0) -> 0.94040734 | L10: =IF(K10>=89.5%,90%,0%) -> 0.9 | M10: 26110040 | N10: 11851681 | O10: =IFERROR(N10/M10,0) -> 0.45391279 | P10: =IF(O10>=89.5%,90%,0%) -> 0 | Q10: 17361288 | R10: 16442528 | S10: =IFERROR(R10/Q10,0) -> 0.94707997 | T10: =IF(S10>=89.5%,90%,0%) -> 0.9 | U10: 27982608 | V10: =VLOOKUP(B10,'Dealer Wise'!B9:F129,5,0) -> 30642958 | W10: =IFERROR(V10/U10,0) -> 1.0950716 | X10: =IF(W10>=89.5%,90%,0%) -> 0.9 | Y10: =E10+I10+M10+Q10+U10 -> 1.2112251e+08 | Z10: =F10+J10+N10+R10+V10 -> 1.0500915e+08 | AA10: =IFERROR(Z10/Y10,0) -> 0.86696639 | AB10: =Y10-Z10 -> 16113365 | AC10: =AB10/AC$2 -> 16113365
A11: 7 | B11: Trade plus | C11: Dhaka North | D11: Mirpur | E11: 6896011.5 | F11: 6949645.6 | G11: =IFERROR(F11/E11,0) -> 1.0077775 | H11: =IF(G11>=89.5%,90%,0%) -> 0.9 | I11: 6572328.1 | J11: 6621142.5 | K11: =IFERROR(J11/I11,0) -> 1.0074273 | L11: =IF(K11>=89.5%,90%,0%) -> 0.9 | M11: 6965120.3 | N11: 4072595.2 | O11: =IFERROR(N11/M11,0) -> 0.58471283 | P11: =IF(O11>=89.5%,90%,0%) -> 0 | Q11: 6322222.3 | R11: 1888384.2 | S11: =IFERROR(R11/Q11,0) -> 0.29868994 | T11: =IF(S11>=89.5%,90%,0%) -> 0 | U11: 8265601.5 | V11: =VLOOKUP(B11,'Dealer Wise'!B10:F130,5,0) -> 8466022.9 | W11: =IFERROR(V11/U11,0) -> 1.0242477 | X11: =IF(W11>=89.5%,90%,0%) -> 0.9 | Y11: =E11+I11+M11+Q11+U11 -> 35021284 | Z11: =F11+J11+N11+R11+V11 -> 27997790 | AA11: =IFERROR(Z11/Y11,0) -> 0.79945072 | AB11: =Y11-Z11 -> 7023493.3 | AC11: =AB11/AC$2 -> 7023493.3
A12: 8 | B12: Star Telecom | C12: Dhaka North | D12: Savar | E12: 7016253.3 | F12: 7023259.4 | G12: =IFERROR(F12/E12,0) -> 1.0009985 | H12: =IF(G12>=89.5%,90%,0%) -> 0.9 | I12: 6965260.2 | J12: 6694113.1 | K12: =IFERROR(J12/I12,0) -> 0.96107151 | L12: =IF(K12>=89.5%,90%,0%) -> 0.9 | M12: 6912801.6 | N12: 4148108.8 | O12: =IFERROR(N12/M12,0) -> 0.60006189 | P12: =IF(O12>=89.5%,90%,0%) -> 0 | Q12: 6033147.3 | R12: 6787207 | S12: =IFERROR(R12/Q12,0) -> 1.1249861 | T12: =IF(S12>=89.5%,90%,0%) -> 0.9 | U12: 8672771.8 | V12: =VLOOKUP(B12,'Dealer Wise'!B11:F131,5,0) -> 9250627.4 | W12: =IFERROR(V12/U12,0) -> 1.0666287 | X12: =IF(W12>=89.5%,90%,0%) -> 0.9 | Y12: =E12+I12+M12+Q12+U12 -> 35600234 | Z12: =F12+J12+N12+R12+V12 -> 33903316 | AA12: =IFERROR(Z12/Y12,0) -> 0.95233406 | AB12: =Y12-Z12 -> 1696918.5 | AC12: =AB12/AC$2 -> 1696918.5
A13: 9 | B13: Zaara Corporation | C13: Dhaka North | D13: Savar | E13: 15861346 | F13: 14438925 | G13: =IFERROR(F13/E13,0) -> 0.91032156 | H13: =IF(G13>=89.5%,90%,0%) -> 0.9 | I13: 15806537 | J13: 15830032 | K13: =IFERROR(J13/I13,0) -> 1.0014864 | L13: =IF(K13>=89.5%,90%,0%) -> 0.9 | M13: 15402436 | N13: 9320422.6 | O13: =IFERROR(N13/M13,0) -> 0.60512651 | P13: =IF(O13>=89.5%,90%,0%) -> 0 | Q13: 19424581 | R13: 16282265 | S13: =IFERROR(R13/Q13,0) -> 0.83822992 | T13: =IF(S13>=89.5%,90%,0%) -> 0 | U13: 19367585 | V13: =VLOOKUP(B13,'Dealer Wise'!B12:F132,5,0) -> 21975071 | W13: =IFERROR(V13/U13,0) -> 1.1346314 | X13: =IF(W13>=89.5%,90%,0%) -> 0.9 | Y13: =E13+I13+M13+Q13+U13 -> 85862486 | Z13: =F13+J13+N13+R13+V13 -> 77846716 | AA13: =IFERROR(Z13/Y13,0) -> 0.9066441 | AB13: =Y13-Z13 -> 8015769.3 | AC13: =AB13/AC$2 -> 8015769.3
A14: 10 | B14: One Telecom (CTG Road) | C14: Dhaka South | D14: Narayangonj | E14: 13685260 | F14: 12513322 | G14: =IFERROR(F14/E14,0) -> 0.91436495 | H14: =IF(G14>=89.5%,90%,0%) -> 0.9 | I14: 14002215 | J14: 9679959.8 | K14: =IFERROR(J14/I14,0) -> 0.69131633 | L14: =IF(K14>=89.5%,90%,0%) -> 0 | M14: 13703135 | N14: 5783499.5 | O14: =IFERROR(N14/M14,0) -> 0.42205665 | P14: =IF(O14>=89.5%,90%,0%) -> 0 | Q14: 9066793.2 | R14: 4263316.7 | S14: =IFERROR(R14/Q14,0) -> 0.47021219 | T14: =IF(S14>=89.5%,90%,0%) -> 0 | U14: 16047731 | V14: =VLOOKUP(B14,'Dealer Wise'!B13:F133,5,0) -> 20714177 | W14: =IFERROR(V14/U14,0) -> 1.2907854 | X14: =IF(W14>=89.5%,90%,0%) -> 0.9 | Y14: =E14+I14+M14+Q14+U14 -> 66505135 | Z14: =F14+J14+N14+R14+V14 -> 52954275 | AA14: =IFERROR(Z14/Y14,0) -> 0.7962434 | AB14: =Y14-Z14 -> 13550860 | AC14: =AB14/AC$2 -> 13550860
A15: 11 | B15: M K Trading Co. | C15: Dhaka South | D15: Narshingdi | E15: 8701407 | F15: 7929466.1 | G15: =IFERROR(F15/E15,0) -> 0.9112855 | H15: =IF(G15>=89.5%,90%,0%) -> 0.9 | I15: 9077948.9 | J15: 4184153.7 | K15: =IFERROR(J15/I15,0) -> 0.46091399 | L15: =IF(K15>=89.5%,90%,0%) -> 0 | M15: 7753631.1 | N15: 5840770.4 | O15: =IFERROR(N15/M15,0) -> 0.75329485 | P15: =IF(O15>=89.5%,90%,0%) -> 0 | Q15: 6403039.2 | R15: 5549698.2 | S15: =IFERROR(R15/Q15,0) -> 0.86672877 | T15: =IF(S15>=89.5%,90%,0%) -> 0 | U15: 7324268.2 | V15: =VLOOKUP(B15,'Dealer Wise'!B14:F134,5,0) -> 9421253.6 | W15: =IFERROR(V15/U15,0) -> 1.2863065 | X15: =IF(W15>=89.5%,90%,0%) -> 0.9 | Y15: =E15+I15+M15+Q15+U15 -> 39260294 | Z15: =F15+J15+N15+R15+V15 -> 32925342 | AA15: =IFERROR(Z15/Y15,0) -> 0.83864226 | AB15: =Y15-Z15 -> 6334952.4 | AC15: =AB15/AC$2 -> 6334952.4
A16: 12 | B16: Ananda Electronics | C16: Dhaka South | D16: Shantinagar | E16: 5476783.3 | F16: 4446004.1 | G16: =IFERROR(F16/E16,0) -> 0.81179112 | H16: =IF(G16>=89.5%,90%,0%) -> 0 | I16: 6469583.7 | J16: 3993599.7 | K16: =IFERROR(J16/I16,0) -> 0.61728851 | L16: =IF(K16>=89.5%,90%,0%) -> 0 | M16: 4363777.8 | N16: 1776728.7 | O16: =IFERROR(N16/M16,0) -> 0.40715379 | P16: =IF(O16>=89.5%,90%,0%) -> 0 | Q16: 4000974.1 | R16: 4316090.5 | S16: =IFERROR(R16/Q16,0) -> 1.0787599 | T16: =IF(S16>=89.5%,90%,0%) -> 0.9 | U16: 6358681.2 | V16: =VLOOKUP(B16,'Dealer Wise'!B15:F135,5,0) -> 8976005.1 | W16: =IFERROR(V16/U16,0) -> 1.4116143 | X16: =IF(W16>=89.5%,90%,0%) -> 0.9 | Y16: =E16+I16+M16+Q16+U16 -> 26669800 | Z16: =F16+J16+N16+R16+V16 -> 23508428 | AA16: =IFERROR(Z16/Y16,0) -> 0.88146247 | AB16: =Y16-Z16 -> 3161372.1 | AC16: =AB16/AC$2 -> 3161372.1
A17: 13 | B17: Taj Telecom | C17: Dhaka South | D17: Dhanmondi | E17: 8730470.1 | F17: 2747935.2 | G17: =IFERROR(F17/E17,0) -> 0.31475226 | H17: =IF(G17>=89.5%,90%,0%) -> 0 | I17: 6700617.8 | J17: 3534105.8 | K17: =IFERROR(J17/I17,0) -> 0.52742985 | L17: =IF(K17>=89.5%,90%,0%) -> 0 | M17: 4955036.7 | N17: 1718410.5 | O17: =IFERROR(N17/M17,0) -> 0.34680076 | P17: =IF(O17>=89.5%,90%,0%) -> 0 | Q17: 2839901.9 | R17: 3370138.6 | S17: =IFERROR(R17/Q17,0) -> 1.1867095 | T17: =IF(S17>=89.5%,90%,0%) -> 0.9 | U17: 6925170 | V17: =VLOOKUP(B17,'Dealer Wise'!B16:F136,5,0) -> 2134036 | W17: =IFERROR(V17/U17,0) -> 0.30815648 | X17: =IF(W17>=89.5%,90%,0%) -> 0 | Y17: =E17+I17+M17+Q17+U17 -> 30151196 | Z17: =F17+J17+N17+R17+V17 -> 13504626 | AA17: =IFERROR(Z17/Y17,0) -> 0.44789686 | AB17: =Y17-Z17 -> 16646570 | AC17: =AB17/AC$2 -> 16646570
... A20: 16 | B20: One Telecom, Narayangonj | C20: Dhaka South | D20: Narayangonj | E20: 12287767 | F20: 11228953 | G20: =IFERROR(F20/E20,0) -> 0.91383188 | H20: =IF(G20>=89.5%,90%,0%) -> 0.9 | I20: 11631810 | J20: 9319153.3 | K20: =IFERROR(J20/I20,0) -> 0.80117828 | L20: =IF(K20>=89.5%,90%,0%) -> 0 | M20: 10956964 | N20: 3728606.7 | O20: =IFERROR(N20/M20,0) -> 0.34029561 | P20: =IF(O20>=89.5%,90%,0%) -> 0 | Q20: 7025617.9 | R20: 5978094.2 | S20: =IFERROR(R20/Q20,0) -> 0.85089942 | T20: =IF(S20>=89.5%,90%,0%) -> 0 | U20: 12518444 | V20: =VLOOKUP(B20,'Dealer Wise'!B19:F139,5,0) -> 14968281 | W20: =IFERROR(V20/U20,0) -> 1.1956982 | X20: =IF(W20>=89.5%,90%,0%) -> 0.9 | Y20: =E20+I20+M20+Q20+U20 -> 54420602 | Z20: =F20+J20+N20+R20+V20 -> 45223088 | AA20: =IFERROR(Z20/Y20,0) -> 0.83099206 | AB20: =Y20-Z20 -> 9197513.9 | AC20: =AB20/AC$2 -> 9197513.9
A21: 17 | B21: Tahia Enterprise | C21: Dhaka South | D21: Narayangonj | E21: 8345031.5 | F21: 8381093.7 | G21: =IFERROR(F21/E21,0) -> 1.0043214 | H21: =IF(G21>=89.5%,90%,0%) -> 0.9 | I21: 8772977.8 | J21: 5906750 | K21: =IFERROR(J21/I21,0) -> 0.67328906 | L21: =IF(K21>=89.5%,90%,0%) -> 0 | M21: 7753631.1 | N21: 5468520.7 | O21: =IFERROR(N21/M21,0) -> 0.70528513 | P21: =IF(O21>=89.5%,90%,0%) -> 0 | Q21: 6100130.4 | R21: 6783091.4 | S21: =IFERROR(R21/Q21,0) -> 1.1119584 | T21: =IF(S21>=89.5%,90%,0%) -> 0.9 | U21: 8136031.6 | V21: =VLOOKUP(B21,'Dealer Wise'!B20:F140,5,0) -> 10039194 | W21: =IFERROR(V21/U21,0) -> 1.2339177 | X21: =IF(W21>=89.5%,90%,0%) -> 0.9 | Y21: =E21+I21+M21+Q21+U21 -> 39107802 | Z21: =F21+J21+N21+R21+V21 -> 36578649 | AA21: =IFERROR(Z21/Y31,0) -> 0.20758913 | AB21: =Y31-Z21 -> 1.3962831e+08 | AC21: =AB21/AC$2 -> 1.3962831e+08
A22: 18 | B22: Anika Traders | C22: Dhaka South | D22: Jatrabari | E22: 7267570.9 | F22: 5922143.8 | G22: =IFERROR(F22/E22,0) -> 0.81487252 | H22: =IF(G22>=89.5%,90%,0%) -> 0 | I22: 7013095.6 | J22: 5614677.6 | K22: =IFERROR(J22/I22,0) -> 0.80059905 | L22: =IF(K22>=89.5%,90%,0%) -> 0 | M22: 6552441.2 | N22: 4278936.1 | O22: =IFERROR(N22/M22,0) -> 0.6530293 | P22: =IF(O22>=89.5%,90%,0%) -> 0 | Q22: 5005247.1 | R22: 2436957.8 | S22: =IFERROR(R22/Q22,0) -> 0.48688062 | T22: =IF(S22>=89.5%,90%,0%) -> 0 | U22: 7613818 | V22: =VLOOKUP(B22,'Dealer Wise'!B21:F141,5,0) -> 6568038.6 | W22: =IFERROR(V22/U22,0) -> 0.86264718 | X22: =IF(W22>=89.5%,90%,0%) -> 0 | Y22: =E22+I22+M22+Q22+U22 -> 33452173 | Z22: =F22+J22+N22+R22+V22 -> 24820754 | AA22: =IFERROR(Z22/Y32,0) -> 0.27561197 | AB22: =Y32-Z22 -> 65236125 | AC22: =AB22/AC$2 -> 65236125
A23: 19 | B23: Mehereen Telecom | C23: Dhaka South | D23: Munshigonj | E23: 11256993 | F23: 9206764.4 | G23: =IFERROR(F23/E23,0) -> 0.81787067 | H23: =IF(G23>=89.5%,90%,0%) -> 0 | I23: 11059256 | J23: 5388835.8 | K23: =IFERROR(J23/I23,0) -> 0.48726931 | L23: =IF(K23>=89.5%,90%,0%) -> 0 | M23: 10575100 | N23: 6228991.5 | O23: =IFERROR(N23/M23,0) -> 0.58902438 | P23: =IF(O23>=89.5%,90%,0%) -> 0 | Q23: 7819923 | R23: 6348798.5 | S23: =IFERROR(R23/Q23,0) -> 0.8118748 | T23: =IF(S23>=89.5%,90%,0%) -> 0 | U23: 11322607 | V23: =VLOOKUP(B23,'Dealer Wise'!B22:F142,5,0) -> 13666723 | W23: =IFERROR(V23/U23,0) -> 1.2070297 | X23: =IF(W23>=89.5%,90%,0%) -> 0.9 | Y23: =E23+I23+M23+Q23+U23 -> 52033878 | Z23: =F23+J23+N23+R23+V23 -> 40840113 | AA23: =IFERROR(Z23/Y33,0) -> 1.6098809 | AB23: =Y33-Z23 -> -15471707 | AC23: =AB23/AC$2 -> -15471707
A24: 20 | B24: Nishat Telecom | C24: Dhaka South | D24: Shantinagar | E24: 10010926 | F24: 8658426.9 | G24: =IFERROR(F24/E24,0) -> 0.86489774 | H24: =IF(G24>=89.5%,90%,0%) -> 0 | I24: 10514524 | J24: 10566830 | K24: =IFERROR(J24/I24,0) -> 1.0049747 | L24: =IF(K24>=89.5%,90%,0%) -> 0.9 | M24: 9673349.1 | N24: 4989026.5 | O24: =IFERROR(N24/M24,0) -> 0.51574966 | P24: =IF(O24>=89.5%,90%,0%) -> 0 | Q24: 9746918.3 | R24: 9963733.7 | S24: =IFERROR(R24/Q24,0) -> 1.0222445 | T24: =IF(S24>=89.5%,90%,0%) -> 0.9 | U24: 11237412 | V24: =VLOOKUP(B24,'Dealer Wise'!B23:F143,5,0) -> 14618145 | W24: =IFERROR(V24/U24,0) -> 1.3008462 | X24: =IF(W24>=89.5%,90%,0%) -> 0.9 | Y24: =E24+I24+M24+Q24+U24 -> 51183129 | Z24: =F24+J24+N24+R24+V24 -> 48796163 | AA24: =IFERROR(Z24/Y34,0) -> 0.78205387 | AB24: =Y34-Z24 -> 13598724 | AC24: =AB24/AC$2 -> 13598724
A25: 21 | B25: One Telecom | C25: Dhaka South | D25: Paltan | E25: 14840547 | F25: 16510229 | G25: =IFERROR(F25/E25,0) -> 1.1125081 | H25: =IF(G25>=89.5%,90%,0%) -> 0.9 | I25: 15433097 | J25: 12789230 | K25: =IFERROR(J25/I25,0) -> 0.82868855 | L25: =IF(K25>=89.5%,90%,0%) -> 0 | M25: 14015290 | N25: 7697075 | O25: =IFERROR(N25/M25,0) -> 0.5491913 | P25: =IF(O25>=89.5%,90%,0%) -> 0 | Q25: 11258297 | R25: 6792778 | S25: =IFERROR(R25/Q25,0) -> 0.6033575 | T25: =IF(S25>=89.5%,90%,0%) -> 0 | U25: 15204681 | V25: =VLOOKUP(B25,'Dealer Wise'!B24:F144,5,0) -> 24365614 | W25: =IFERROR(V25/U25,0) -> 1.6025074 | X25: =IF(W25>=89.5%,90%,0%) -> 0.9 | Y25: =E25+I25+M25+Q25+U25 -> 70751911 | Z25: =F25+J25+N25+R25+V25 -> 68154926 | AA25: =IFERROR(Z25/Y35,0) -> 1.3951027 | AB25: =Y35-Z25 -> -19301946 | AC25: =AB25/AC$2 -> -19301946
A26: 22 | B26: One Telecom, Jatrabari | C26: Dhaka South | D26: Jatrabari | E26: 8466647.4 | F26: 7690130.7 | G26: =IFERROR(F26/E26,0) -> 0.90828522 | H26: =IF(G26>=89.5%,90%,0%) -> 0.9 | I26: 9035879.4 | J26: 7874551 | K26: =IFERROR(J26/I26,0) -> 0.87147588 | L26: =IF(K26>=89.5%,90%,0%) -> 0 | M26: 9470719.9 | N26: 6058092.4 | O26: =IFERROR(N26/M26,0) -> 0.63966546 | P26: =IF(O26>=89.5%,90%,0%) -> 0 | Q26: 7834208.2 | R26: 4001812.6 | S26: =IFERROR(R26/Q26,0) -> 0.51081264 | T26: =IF(S26>=89.5%,90%,0%) -> 0 | U26: 9949681.5 | V26: =VLOOKUP(B26,'Dealer Wise'!B25:F145,5,0) -> 13224640 | W26: =IFERROR(V26/U26,0) -> 1.3291521 | X26: =IF(W26>=89.5%,90%,0%) -> 0.9 | Y26: =E26+I26+M26+Q26+U26 -> 44757136 | Z26: =F26+J26+N26+R26+V26 -> 38849226 | AA26: =IFERROR(Z26/Y36,0) -> 0.53541877 | AB26: =Y36-Z26 -> 33709355 | AC26: =AB26/AC$2 -> 33709355
A27: 23 | B27: F N Traders | C27: Dhaka North | D27: Gazipur | E27: 5658323.2 | F27: 3566355 | G27: =IFERROR(F27/E27,0) -> 0.63028479 | H27: =IF(G27>=89.5%,90%,0%) -> 0 | I27: 5453825.6 | J27: 2972089.5 | K27: =IFERROR(J27/I27,0) -> 0.544955 | L27: =IF(K27>=89.5%,90%,0%) -> 0 | M27: 3900046.3 | N27: 2167455.4 | O27: =IFERROR(N27/M27,0) -> 0.55575119 | P27: =IF(O27>=89.5%,90%,0%) -> 0 | Q27: 7976320.6 | R27: 9664592.2 | S27: =IFERROR(R27/Q27,0) -> 1.2116605 | T27: =IF(S27>=89.5%,90%,0%) -> 0.9 | U27: 4983838 | V27: =VLOOKUP(B27,'Dealer Wise'!B26:F146,5,0) -> 8442394.1 | W27: =IFERROR(V27/U27,0) -> 1.6939544 | X27: =IF(W27>=89.5%,90%,0%) -> 0.9 | Y27: =E27+I27+M27+Q27+U27 -> 27972354 | Z27: =F27+J27+N27+R27+V27 -> 26812886 | AA27: =IFERROR(Z27/Y37,0) -> 0.92764898 | AB27: =Y37-Z27 -> 2091243.3 | AC27: =AB27/AC$2 -> 2091243.3
A28: 24 | B28: Rathura Enterprise – 2 | C28: Dhaka North | D28: Gazipur | E28: 6044659.8 | F28: 6298732 | G28: =IFERROR(F28/E28,0) -> 1.0420325 | H28: =IF(G28>=89.5%,90%,0%) -> 0.9 | I28: 9169049.7 | J28: 9359171.4 | K28: =IFERROR(J28/I28,0) -> 1.0207352 | L28: =IF(K28>=89.5%,90%,0%) -> 0.9 | M28: 9420009.5 | N28: 4571803.5 | O28: =IFERROR(N28/M28,0) -> 0.48532897 | P28: =IF(O28>=89.5%,90%,0%) -> 0 | Q28: 7688847.6 | R28: 7845078 | S28: =IFERROR(R28/Q28,0) -> 1.0203191 | T28: =IF(S28>=89.5%,90%,0%) -> 0.9 | U28: 10777373 | V28: =VLOOKUP(B28,'Dealer Wise'!B27:F147,5,0) -> 14884903 | W28: =IFERROR(V28/U28,0) -> 1.3811254 | X28: =IF(W28>=89.5%,90%,0%) -> 0.9 | Y28: =E28+I28+M28+Q28+U28 -> 43099939 | Z28: =F28+J28+N28+R28+V28 -> 42959688 | AA28: =IFERROR(Z28/Y38,0) -> 1.7904805 | AB28: =Y38-Z28 -> -18966303 | AC28: =AB28/AC$2 -> -18966303
A29: 25 | B29: M/S. Sumon Telecoms | C29: Dhaka North | D29: Mymensingh | E29: 2326781.4 | F29: 207401.81 | G29: =IFERROR(F29/E29,0) -> 0.089136786 | H29: =IF(G29>=89.5%,90%,0%) -> 0 | I29: 2178753.2 | J29: 1885969.7 | K29: =IFERROR(J29/I29,0) -> 0.86561877 | L29: =IF(K29>=89.5%,90%,0%) -> 0 | M29: 2505467.9 | N29: 1005820.9 | O29: =IFERROR(N29/M29,0) -> 0.40145034 | P29: =IF(O29>=89.5%,90%,0%) -> 0 | Q29: 3246047.9 | R29: 1500897.3 | S29: =IFERROR(R29/Q29,0) -> 0.46237684 | T29: =IF(S29>=89.5%,90%,0%) -> 0 | U29: 1837611.1 | V29: =VLOOKUP(B29,'Dealer Wise'!B28:F148,5,0) -> 1872031 | W29: =IFERROR(V29/U29,0) -> 1.0187308 | X29: =IF(W29>=89.5%,90%,0%) -> 0.9 | Y29: =E29+I29+M29+Q29+U29 -> 12094661 | Z29: =F29+J29+N29+R29+V29 -> 6472120.7 | AA29: =IFERROR(Z29/Y39,0) -> 0.10807831 | AB29: =Y39-Z29 -> 53411502 | AC29: =AB29/AC$2 -> 53411502
A30: 26 | B30: Mobile Point | C30: Dhaka North | D30: Gazipur | E30: 5467555.9 | F30: 5259150.5 | G30: =IFERROR(F30/E30,0) -> 0.96188327 | H30: =IF(G30>=89.5%,90%,0%) -> 0.9 | I30: 4693554.9 | J30: 4737512.8 | K30: =IFERROR(J30/I30,0) -> 1.0093656 | L30: =IF(K30>=89.5%,90%,0%) -> 0.9 | M30: 5411113.6 | N30: 3289042.3 | O30: =IFERROR(N30/M30,0) -> 0.60783095 | P30: =IF(O30>=89.5%,90%,0%) -> 0 | Q30: 4555794.9 | R30: 4988156.9 | S30: =IFERROR(R30/Q30,0) -> 1.0949038 | T30: =IF(S30>=89.5%,90%,0%) -> 0.9 | U30: 5468353.3 | V30: =VLOOKUP(B30,'Dealer Wise'!B29:F149,5,0) -> 7614226.5 | W30: =IFERROR(V30/U30,0) -> 1.3924167 | X30: =IF(W30>=89.5%,90%,0%) -> 0.9 | Y30: =E30+I30+M30+Q30+U30 -> 25596373 | Z30: =F30+J30+N30+R30+V30 -> 25888089 | AA30: =IFERROR(Z30/Y40,0) -> 0.65813029 | AB30: =Y40-Z30 -> 13447723 | AC30: =AB30/AC$2 -> 13447723
A31: 27 | B31: Rathura Enterprise | C31: Dhaka North | D31: Gazipur | E31: 36189056 | F31: 36581898 | G31: =IFERROR(F31/E31,0) -> 1.0108553 | H31: =IF(G31>=89.5%,90%,0%) -> 0.9 | I31: 36204566 | J31: 36404334 | K31: =IFERROR(J31/I31,0) -> 1.0055178 | L31: =IF(K31>=89.5%,90%,0%) -> 0.9 | M31: 36642508 | N31: 18042690 | O31: =IFERROR(N31/M31,0) -> 0.4923978 | P31: =IF(O31>=89.5%,90%,0%) -> 0 | Q31: 29503982 | R31: 29666880 | S31: =IFERROR(R31/Q31,0) -> 1.0055212 | T31: =IF(S31>=89.5%,90%,0%) -> 0.9 | U31: 37666846 | V31: =VLOOKUP(B31,'Dealer Wise'!B30:F150,5,0) -> 52729026 | W31: =IFERROR(V31/U31,0) -> 1.399879 | X31: =IF(W31>=89.5%,90%,0%) -> 0.9 | Y31: =E31+I31+M31+Q31+U31 -> 1.7620696e+08 | Z31: =F31+J31+N31+R31+V31 -> 1.7342483e+08 | AA31: =IFERROR(Z31/Y31,0) -> 0.98421101 | AB31: =Y31-Z31 -> 2782129.8 | AC31: =AB31/AC$2 -> 2782129.8
A32: 28 | B32: M/S Siddique Enterprise | C32: Dhaka North | D32: Jamalpur | E32: 18057911 | F32: 17576176 | G32: =IFERROR(F32/E32,0) -> 0.97332276 | H32: =IF(G32>=89.5%,90%,0%) -> 0.9 | I32: 18128278 | J32: 16510217 | K32: =IFERROR(J32/I32,0) -> 0.91074381 | L32: =IF(K32>=89.5%,90%,0%) -> 0.9 | M32: 16773490 | N32: 9536764.9 | O32: =IFERROR(N32/M32,0) -> 0.56856175 | P32: =IF(O32>=89.5%,90%,0%) -> 0 | Q32: 16564828 | R32: 20110720 | S32: =IFERROR(R32/Q32,0) -> 1.2140615 | T32: =IF(S32>=89.5%,90%,0%) -> 0.9 | U32: 20532372 | V32: =VLOOKUP(B32,'Dealer Wise'!B4:F124,5,0) -> 18441931 | W32: =IFERROR(V32/U32,0) -> 0.89818808 | X32: =IF(W32>=89.5%,90%,0%) -> 0.9 | Y32: =E32+I32+M32+Q32+U32 -> 90056879 | Z32: =F32+J32+N32+R32+V32 -> 82175810 | AA32: =IFERROR(Z32/Y32,0) -> 0.91248787 | AB32: =Y32-Z32 -> 7881069.3 | AC32: =AB32/AC$2 -> 7881069.3
A33: 29 | B33: Priyo Telecom | C33: Dhaka North | D33: Tangail | E33: 4092843.5 | F33: 4759278.4 | G33: =IFERROR(F33/E33,0) -> 1.1628293 | H33: =IF(G33>=89.5%,90%,0%) -> 0.9 | I33: 4769847.4 | J33: 4854607.6 | K33: =IFERROR(J33/I33,0) -> 1.01777 | L33: =IF(K33>=89.5%,90%,0%) -> 0.9 | M33: 5306923.6 | N33: 3525944.7 | O33: =IFERROR(N33/M33,0) -> 0.66440466 | P33: =IF(O33>=89.5%,90%,0%) -> 0 | Q33: 5908296.3 | R33: 6473011.4 | S33: =IFERROR(R33/Q33,0) -> 1.09558 | T33: =IF(S33>=89.5%,90%,0%) -> 0.9 | U33: 5290495.5 | V33: =VLOOKUP(B33,'Dealer Wise'!B32:F152,5,0) -> 6167709.9 | W33: =IFERROR(V33/U33,0) -> 1.1658095 | X33: =IF(W33>=89.5%,90%,0%) -> 0.9 | Y33: =E33+I33+M33+Q33+U33 -> 25368406 | Z33: =F33+J33+N33+R33+V33 -> 25780552 | AA33: =IFERROR(Z33/Y33,0) -> 1.0162464 | AB33: =Y33-Z33 -> -412145.77 | AC33: =AB33/AC$2 -> -412145.77
A34: 30 | B34: Repon Enterprise | C34: Dhaka North | D34: Netrokona | E34: 11359254 | F34: 11958386 | G34: =IFERROR(F34/E34,0) -> 1.0527439 | H34: =IF(G34>=89.5%,90%,0%) -> 0.9 | I34: 12229300 | J34: 11144410 | K34: =IFERROR(J34/I34,0) -> 0.91128763 | L34: =IF(K34>=89.5%,90%,0%) -> 0.9 | M34: 12014734 | N34: 5997877.5 | O34: =IFERROR(N34/M34,0) -> 0.49921016 | P34: =IF(O34>=89.5%,90%,0%) -> 0 | Q34: 11580126 | R34: 13451293 | S34: =IFERROR(R34/Q34,0) -> 1.1615844 | T34: =IF(S34>=89.5%,90%,0%) -> 0.9 | U34: 15211473 | V34: =VLOOKUP(B34,'Dealer Wise'!B33:F153,5,0) -> 16584227 | W34: =IFERROR(V34/U34,0) -> 1.0902446 | X34: =IF(W34>=89.5%,90%,0%) -> 0.9 | Y34: =E34+I34+M34+Q34+U34 -> 62394887 | Z34: =F34+J34+N34+R34+V34 -> 59136192 | AA34: =IFERROR(Z34/Y34,0) -> 0.94777305 | AB34: =Y34-Z34 -> 3258694.5 | AC34: =AB34/AC$2 -> 3258694.5
A35: 31 | B35: M/S Saidur Electronics | C35: Dhaka North | D35: Mymensingh | E35: 8751896 | F35: 8755764.6 | G35: =IFERROR(F35/E35,0) -> 1.000442 | H35: =IF(G35>=89.5%,90%,0%) -> 0.9 | I35: 8868116 | J35: 9483601.4 | K35: =IFERROR(J35/I35,0) -> 1.0694043 | L35: =IF(K35>=89.5%,90%,0%) -> 0.9 | M35: 8810214.6 | N35: 8205083.4 | O35: =IFERROR(N35/M35,0) -> 0.93131482 | P35: =IF(O35>=89.5%,90%,0%) -> 0.9 | Q35: 12023736 | R35: 15207928 | S35: =IFERROR(R35/Q35,0) -> 1.2648255 | T35: =IF(S35>=89.5%,90%,0%) -> 0.9 | U35: 10399017 | V35: =VLOOKUP(B35,'Dealer Wise'!B7:F127,5,0) -> 15115605 | W35: =IFERROR(V35/U35,0) -> 1.4535609 | X35: =IF(W35>=89.5%,90%,0%) -> 0.9 | Y35: =E35+I35+M35+Q35+U35 -> 48852980 | Z35: =F35+J35+N35+R35+V35 -> 56767983 | AA35: =IFERROR(Z35/Y35,0) -> 1.1620168 | AB35: =Y35-Z35 -> -7915002.7 | AC35: =AB35/AC$2 -> -7915002.7
A36: 32 | B36: M/S Zaman Enterprise | C36: Dhaka North | D36: Mymensingh | E36: 14114289 | F36: 4397166.2 | G36: =IFERROR(F36/E36,0) -> 0.31154004 | H36: =IF(G36>=89.5%,90%,0%) -> 0 | I36: 13171231 | J36: 13236078 | K36: =IFERROR(J36/I36,0) -> 1.0049234 | L36: =IF(K36>=89.5%,90%,0%) -> 0.9 | M36: 15022690 | N36: 6802140.9 | O36: =IFERROR(N36/M36,0) -> 0.45279115 | P36: =IF(O36>=89.5%,90%,0%) -> 0 | Q36: 15045238 | R36: 15106263 | S36: =IFERROR(R36/Q36,0) -> 1.0040561 | T36: =IF(S36>=89.5%,90%,0%) -> 0.9 | U36: 15205134 | V36: =VLOOKUP(B36,'Dealer Wise'!B8:F128,5,0) -> 21084970 | W36: =IFERROR(V36/U36,0) -> 1.3867007 | X36: =IF(W36>=89.5%,90%,0%) -> 0.9 | Y36: =E36+I36+M36+Q36+U36 -> 72558582 | Z36: =F36+J36+N36+R36+V36 -> 60626618 | AA36: =IFERROR(Z36/Y36,0) -> 0.83555407 | AB36: =Y36-Z36 -> 11931963 | AC36: =AB36/AC$2 -> 11931963
A37: 33 | B37: Shisha Stationary & Electronics | C37: Dhaka North | D37: Mymensingh | E37: 4985965.3 | F37: 5267295.6 | G37: =IFERROR(F37/E37,0) -> 1.0564244 | H37: =IF(G37>=89.5%,90%,0%) -> 0.9 | I37: 5138726.7 | J37: 6039191.2 | K37: =IFERROR(J37/I37,0) -> 1.1752311 | L37: =IF(K37>=89.5%,90%,0%) -> 0.9 | M37: 5554870.3 | N37: 4388863.7 | O37: =IFERROR(N37/M37,0) -> 0.79009292 | P37: =IF(O37>=89.5%,90%,0%) -> 0 | Q37: 6716798.8 | R37: 7327165 | S37: =IFERROR(R37/Q37,0) -> 1.0908716 | T37: =IF(S37>=89.5%,90%,0%) -> 0.9 | U37: 6507768.5 | V37: =VLOOKUP(B37,'Dealer Wise'!B36:F156,5,0) -> 6942003.7 | W37: =IFERROR(V37/U37,0) -> 1.0667257 | X37: =IF(W37>=89.5%,90%,0%) -> 0.9 | Y37: =E37+I37+M37+Q37+U37 -> 28904130 | Z37: =F37+J37+N37+R37+V37 -> 29964519 | AA37: =IFERROR(Z37/Y37,0) -> 1.0366864 | AB37: =Y37-Z37 -> -1060389.7 | AC37: =AB37/AC$2 -> -1060389.7
A38: 34 | B38: M/S. Sujan Telecom | C38: Dhaka North | D38: Netrokona | E38: 4561648.1 | F38: 4611830.1 | G38: =IFERROR(F38/E38,0) -> 1.0110009 | H38: =IF(G38>=89.5%,90%,0%) -> 0.9 | I38: 4301975.2 | J38: 5121956 | K38: =IFERROR(J38/I38,0) -> 1.1906056 | L38: =IF(K38>=89.5%,90%,0%) -> 0.9 | M38: 4844036.7 | N38: 2604879 | O38: =IFERROR(N38/M38,0) -> 0.53774964 | P38: =IF(O38>=89.5%,90%,0%) -> 0 | Q38: 5593376.5 | R38: 5929536.1 | S38: =IFERROR(R38/Q38,0) -> 1.0600996 | T38: =IF(S38>=89.5%,90%,0%) -> 0.9 | U38: 4692348.7 | V38: =VLOOKUP(B38,'Dealer Wise'!B10:F130,5,0) -> 7831770.3 | W38: =IFERROR(V38/U38,0) -> 1.6690512 | X38: =IF(W38>=89.5%,90%,0%) -> 0.9 | Y38: =E38+I38+M38+Q38+U38 -> 23993385 | Z38: =F38+J38+N38+R38+V38 -> 26099972 | AA38: =IFERROR(Z38/Y38,0) -> 1.0877986 | AB38: =Y38-Z38 -> -2106586.4 | AC38: =AB38/AC$2 -> -2106586.4
A39: 35 | B39: Shaheen Multimedia & Telecom | C39: Dhaka North | D39: Netrokona | E39: 11467512 | F39: 11775999 | G39: =IFERROR(F39/E39,0) -> 1.0269009 | H39: =IF(G39>=89.5%,90%,0%) -> 0.9 | I39: 11194543 | J39: 10780501 | K39: =IFERROR(J39/I39,0) -> 0.96301393 | L39: =IF(K39>=89.5%,90%,0%) -> 0.9 | M39: 12014734 | N39: 5138832.9 | O39: =IFERROR(N39/M39,0) -> 0.4277109 | P39: =IF(O39>=89.5%,90%,0%) -> 0 | Q39: 11370516 | R39: 20634084 | S39: =IFERROR(R39/Q39,0) -> 1.8147007 | T39: =IF(S39>=89.5%,90%,0%) -> 0.9 | U39: 13836316 | V39: =VLOOKUP(B39,'Dealer Wise'!B38:F158,5,0) -> 18801128 | W39: =IFERROR(V39/U39,0) -> 1.3588247 | X39: =IF(W39>=89.5%,90%,0%) -> 0.9 | Y39: =E39+I39+M39+Q39+U39 -> 59883623 | Z39: =F39+J39+N39+R39+V39 -> 67130545 | AA39: =IFERROR(Z39/Y39,0) -> 1.1210168 | AB39: =Y39-Z39 -> -7246922.1 | AC39: =AB39/AC$2 -> -7246922.1
A40: 36 | B40: M/S. Mukul Enterprise | C40: Dhaka North | D40: Jamalpur | E40: 7142539.8 | F40: 7465139.6 | G40: =IFERROR(F40/E40,0) -> 1.045166 | H40: =IF(G40>=89.5%,90%,0%) -> 0.9 | I40: 8262920.9 | J40: 7537088.7 | K40: =IFERROR(J40/I40,0) -> 0.91215792 | L40: =IF(K40>=89.5%,90%,0%) -> 0.9 | M40: 7473254.7 | N40: 3546790.7 | O40: =IFERROR(N40/M40,0) -> 0.47459786 | P40: =IF(O40>=89.5%,90%,0%) -> 0 | Q40: 7798119.9 | R40: 10454228 | S40: =IFERROR(R40/Q40,0) -> 1.3406087 | T40: =IF(S40>=89.5%,90%,0%) -> 0.9 | U40: 8658976.4 | V40: =VLOOKUP(B40,'Dealer Wise'!B12:F132,5,0) -> 12252774 | W40: =IFERROR(V40/U40,0) -> 1.4150372 | X40: =IF(W40>=89.5%,90%,0%) -> 0.9 | Y40: =E40+I40+M40+Q40+U40 -> 39335812 | Z40: =F40+J40+N40+R40+V40 -> 41256021 | AA40: =IFERROR(Z40/Y40,0) -> 1.0488158 | AB40: =Y40-Z40 -> -1920209.1 | AC40: =AB40/AC$2 -> -1920209.1
